
                   ###################################################################### 加工训练账期近n月基础数据
                    
20220617-17:08:58  开始时间：2022-06-17 17:08:58
20220617-17:08:58  ---- month: 202010
20220617-17:08:58  ---- 参数设置：
                       ---- step: train
                       ---- Info.model_name: 模型示例
                       ---- Info.n_recent: 3
                       ---- Info.Pcase_limit: 1000
                       ---- Info.traintable_ratio: 2
                       ---- Info.Pcumsum_limit: 2
                       ---- Info.timein_count: 500

                   ------------------------------------- 检查各前置表 --------------------------------------------------- 
20220617-17:08:58  检查 kehujingyingbudb.ml_xy_eg_m
20220617-17:08:59      78 列


Traceback (most recent call last):
  File "D:\Python for Windows\lib\site-packages\pandas\core\indexes\base.py", line 3361, in get_loc
    return self._engine.get_loc(casted_key)
  File "pandas\_libs\index.pyx", line 76, in pandas._libs.index.IndexEngine.get_loc
  File "pandas\_libs\index.pyx", line 108, in pandas._libs.index.IndexEngine.get_loc
  File "pandas\_libs\hashtable_class_helper.pxi", line 5198, in pandas._libs.hashtable.PyObjectHashTable.get_item
  File "pandas\_libs\hashtable_class_helper.pxi", line 5206, in pandas._libs.hashtable.PyObjectHashTable.get_item
KeyError: '202010'
20220617-17:08:59  
                   The above exception was the direct cause of the following exception:


Traceback (most recent call last):
  File "<ipython-input-15-751810ad9cdb>", line 22, in <module>
    base_train[model_name], Info = privy_basedatafun('train', Info, nmg_yaxin=nmg_yaxin)
  File "D:\工作\模型脚本\ModelProject\selfmodule\tablemodule\tablefun.py", line 672, in privy_basedatafun
    print(f"    {month_i}账期： {mlist_all['count'].loc[str(month_i)]}行")
  File "D:\Python for Windows\lib\site-packages\pandas\core\indexing.py", line 931, in __getitem__
    return self._getitem_axis(maybe_callable, axis=axis)
  File "D:\Python for Windows\lib\site-packages\pandas\core\indexing.py", line 1164, in _getitem_axis
    return self._get_label(key, axis=axis)
  File "D:\Python for Windows\lib\site-packages\pandas\core\indexing.py", line 1113, in _get_label
    return self.obj.xs(label, axis=axis)
  File "D:\Python for Windows\lib\site-packages\pandas\core\generic.py", line 3776, in xs
    loc = index.get_loc(key)
  File "D:\Python for Windows\lib\site-packages\pandas\core\indexes\base.py", line 3363, in get_loc
    raise KeyError(key) from err
KeyError: '202010'
